<?xml version="1.0"?>
<robot name="turtlebot3_burger" xmlns:xacro="http://ros.org/wiki/xacro">

  <xacro:macro name="cylinder_inertia" params="m r h">
    <inertial>
      <mass value="${m}" />
      <inertia ixx="${m*(3*r*r+h*h)/12}" ixy="0.0" ixz="0.0" iyy="${m*(3*r*r+h*h)/12}" iyz="0.0" izz="${m*r*r/2}" />
    </inertial>
  </xacro:macro>


  <!-- Init colour -->
  <material name="black">
    <color rgba="0.0 0.0 0.0 1.0" />
  </material>

  <material name="dark">
    <color rgba="0.3 0.3 0.3 1.0" />
  </material>

  <material name="light_black">
    <color rgba="0.4 0.4 0.4 1.0" />
  </material>

  <material name="blue">
    <color rgba="0.0 0.0 0.8 1.0" />
  </material>

  <material name="green">
    <color rgba="0.0 0.8 0.0 1.0" />
  </material>

  <material name="grey">
    <color rgba="0.5 0.5 0.5 1.0" />
  </material>

  <material name="orange">
    <color rgba="1.0 0.4235 0.0392 1.0" />
  </material>

  <material name="brown">
    <color rgba="0.8706 0.8118 0.7647 1.0" />
  </material>

  <material name="red">
    <color rgba="0.8 0.0 0.0 1.0" />
  </material>

  <material name="white">
    <color rgba="1.0 1.0 1.0 1.0" />
  </material>

  <link name="base_footprint" />

  <joint name="base_joint" type="fixed">
    <parent link="base_footprint" />
    <child link="base_link" />
    <origin xyz="0.0 0.0 0.010" rpy="0 0 0" />
  </joint>

  <link name="base_link">
    <visual>
      <origin xyz="-0.032 0 0.0" rpy="0 0 0" />
      <geometry>
        <mesh filename="package://robot_description/meshes/chassis.STL" />
      </geometry>
      <material name="light_black" />
    </visual>

    <collision>
      <origin xyz="-0.032 0 0.070" rpy="0 0 0" />
      <geometry>
        <mesh filename="package://robot_description/meshes/chassis.STL" />
      </geometry>
    </collision>

    <inertial>
      <origin xyz="0 0 0" rpy="0 0 0" />
      <mass value="8.2573504e-01" />
      <inertia ixx="2.2124416e-03" ixy="-1.2294101e-05" ixz="3.4938785e-05" iyy="2.1193702e-03" iyz="-5.0120904e-06" izz="2.0064271e-03" />
    </inertial>
  </link>

  <!-- laserscan front -->

  <link name="laserscan_front">
    <inertial>
      <origin xyz="0.02471 6.5845E-10 -0.011912" rpy="0 0 0" />
      <mass value="0.32341" />
      <inertia ixx="1.9683E-05" ixy="6.844E-12" ixz="-0.00012644" iyy="0.00083192" iyz="1.0654E-12" izz="0.00081224" />
    </inertial>
    <visual>
      <origin xyz="0 0 0" rpy="0 0 0" />
      <geometry>
        <mesh filename="package://robot_description/meshes/laserscan_front.STL" />
      </geometry>
      <material name="">
        <color rgba="0 0 0 1" />
      </material>
    </visual>
    <collision>
      <origin xyz="0 0 0" rpy="0 0 0" />
      <geometry>
        <mesh filename="package://robot_description/meshes/laserscan_front.STL" />
      </geometry>
    </collision>
  </link>


  <link name="drive_wheel_right">
    <inertial>
      <mass value="1.3118" />
      <inertia ixx="0.001418" ixy="0.0" ixz="0.0" iyy="0.004244" iyz="0.0" izz="0.00677" />
    </inertial>
    <visual>
      <origin xyz="0 0 0" rpy="0 0 0" />
      <geometry>
        <mesh filename="package://robot_description/meshes/drive_wheel_right.STL" />
      </geometry>
      <material name="">
        <color rgba="0.29804 0.29804 0.29804 1" />
      </material>
    </visual>
    <collision>
      <origin xyz="0 0 0" rpy="0 0 0" />
      <geometry>
        <mesh filename="package://robot_description/meshes/drive_wheel_right.STL" />
      </geometry>
    </collision>
  </link>

  <joint name="drive_wheel_right_joint" type="continuous">
    <origin xyz="0.074873 -0.34278 0.086706" rpy="0 0 0" />
    <parent link="base_link" />
    <child link="drive_wheel_right" />
    <axis xyz="0 1 0" />
  </joint>

  <link name="drive_wheel_left">
    <inertial>
      <mass value="1.3118" />
      <inertia ixx="0.001418" ixy="0.0" ixz="0.0" iyy="0.004244" iyz="0.0" izz="0.00677" />
    </inertial>
    <visual>
      <origin xyz="0 0 0" rpy="0 0 0" />
      <geometry>
        <mesh filename="package://robot_description/meshes/drive_wheel_left.STL" />
      </geometry>
      <material name="">
        <color rgba="0.29804 0.29804 0.29804 1" />
      </material>
    </visual>
    <collision>
      <origin xyz="0 0 0" rpy="0 0 0" />
      <geometry>
        <mesh filename="package://robot_description/meshes/drive_wheel_left.STL" />
      </geometry>
    </collision>
  </link>

  <joint name="drive_wheel_left_joint" type="continuous">
    <origin xyz="0.074873 0.34278 0.086706" rpy="0 0 0" />
    <parent link="base_link" />
    <child link="drive_wheel_left" />
    <axis xyz="0 1 0" />
  </joint>

  <joint name="base_link_laserscan_front" type="fixed">
    <origin xyz="0.76419 0.351 0.28335" rpy="0 0 0" />
    <parent link="base_link" />
    <child link="laserscan_front" />
    <axis xyz="0 0 0" />
  </joint>

  <link name="laserscan_back">
    <inertial>
      <origin xyz="0.007429 -9.2927E-10 -0.016915" rpy="0 0 0" />
      <mass value="0.22916" />
      <inertia ixx="0" ixy="0" ixz="0" iyy="0" iyz="0" izz="0" />
    </inertial>
    <visual>
      <origin xyz="0 0 0" rpy="0 0 0" />
      <geometry>
        <mesh filename="package://robot_description/meshes/laserscan_back.STL" />
      </geometry>
      <material name="">
        <color rgba="0 0 0 1" />
      </material>
    </visual>
    <collision>
      <origin xyz="0 0 0" rpy="0 0 0" />
      <geometry>
        <mesh filename="package://robot_description/meshes/laserscan_back.STL" />
      </geometry>
    </collision>
  </link>

  <joint name="base_link_laserscan_back" type="fixed">
    <origin xyz="-0.76419 -0.351 0.28335" rpy="0 0 3.14" />
    <parent link="base_link" />
    <child link="laserscan_back" />
    <axis xyz="0 0 0" />
  </joint>

  <link name="imu_link">
    <inertial>
      <origin xyz="3.3961E-18 3.8417E-18 0.005" rpy="0 0 0" />
      <mass value="0.026795" />
      <inertia ixx="0" ixy="0" ixz="0" iyy="0" iyz="0" izz="0" />
    </inertial>
    <visual>
      <origin xyz="0 0 0" rpy="0 0 0" />
      <geometry>
        <mesh filename="package://robot_description/meshes/imu_adis1647x_pcb.STL" />
      </geometry>
      <material name="">
        <color rgba="0.89804 0.91765 0.92941 1" />
      </material>
    </visual>
    <collision>
      <origin xyz="0 0 0" rpy="0 0 0" />
      <geometry>
        <mesh filename="package://robot_description/meshes/imu_adis1647x_pcb.STL" />
      </geometry>
    </collision>
  </link>

  <joint name="base_imu_link" type="fixed">
    <origin xyz="0 0 0.00122" rpy="0 0 0" />
    <parent link="base_link" />
    <child link="imu_link" />
    <axis xyz="0 0 0" />
  </joint>

</robot>
