<?xml version="1.0"?>
<sdf version="1.5">
    <model name="robot">
        <pose>0.0 0.0 0.0 0.0 0.0 0.0</pose>

        <link name="base_footprint" />

        <link name="base_link">
            <inertial>
                <pose>0 0 0.1 0 0 0</pose>
                <inertia>
                    <ixx>1.07</ixx>
                    <ixy>0</ixy>
                    <ixz>0.09</ixz>
                    <iyy>4.55</iyy>
                    <iyz>0</iyz>
                    <izz>5.30</izz>
                </inertia>
                <mass>49.497</mass>
            </inertial>
            <collision name="base_link_collision">
                <pose>0 0 0 0 0 0</pose>
                <geometry>
                    <mesh>
                        <uri>model://robot/meshes/chassis.STL</uri>
                        <!-- <scale>0.001 0.001 0.001</scale> -->
                    </mesh>
                </geometry>
            </collision>
            <visual name="base_link_visual">
                <pose>0 0 0 0 0 0</pose>
                <geometry>
                    <mesh>
                        <uri>model://robot/meshes/chassis.STL</uri>
                        <!-- <scale>0.001 0.001 0.001</scale> -->
                    </mesh>
                </geometry>
                <material name="light_black"/>
            </visual>
        </link>
        <joint name="base_link_joint" type="fixed">
            <parent>base_footprint</parent>
            <child>base_link</child>
            <pose>0.0 0.0 0.0 0.0 0.0 0.0</pose>
        </joint>

        <link name="drive_wheel_right">
            <inertial>
                <pose>0.074873 -0.34278 0.086706 0 0 0</pose>
                <inertia>
                    <ixx>0.001418</ixx>
                    <ixy>0.0</ixy>
                    <ixz>0.0</ixz>
                    <iyy>0.004244</iyy>
                    <iyz>0.0</iyz>
                    <izz>0.00677</izz>
                </inertia>
                <mass>1.3118</mass>
            </inertial>
            <collision name="drive_wheel_right_collision">
                <pose>0.074873 -0.34278 0.086706 0 0 0</pose>
                <geometry>
                    <mesh>
                        <uri>model://robot/meshes/drive_wheel_right.STL</uri>
                        <!-- <scale>0.001 0.001 0.001</scale> -->
                    </mesh>
                </geometry>
                <!-- <surface>
                    <friction>
                        <ode>
                            <mu>100000.0</mu>
                            <mu2>100000.0</mu2>
                            <fdir1>0 1 0</fdir1>
                            <slip1>0.0</slip1>
                            <slip2>0.0</slip2>
                        </ode>
                    </friction>
                    <contact>
                        <ode>
                            <soft_cfm>0</soft_cfm>
                            <soft_erp>0.2</soft_erp>
                            <kp>1e+5</kp>
                            <kd>1</kd>
                            <max_vel>0.01</max_vel>
                            <min_depth>0.001</min_depth>
                        </ode>
                    </contact>
                </surface> -->
            </collision>
            <visual name="drive_wheel_right_visual">
                <pose>0.074873 -0.34278 0.0867060 0 0</pose>
                <geometry>
                    <mesh>
                        <uri>model://robot/meshes/drive_wheel_right.STL</uri>
                        <!-- <scale>0.001 0.001 0.001</scale> -->
                    </mesh>
                </geometry>
                <material name="dark"/>
            </visual>
        </link>
        <joint name="drive_wheel_right_joint" type="revolute">
            <parent>base_footprint</parent>
            <child>drive_wheel_right</child>
            <pose>0.074873 -0.34278 0.086706 0.0 0.0 0.0</pose>
            <axis>
                <xyz>0 1 0</xyz>
            </axis>
        </joint>

        <link name="drive_wheel_left">
            <inertial>
                <pose>0.074873 0.34278 0.086706 0 0 0</pose>
                <inertia>
                    <ixx>0.001418</ixx>
                    <ixy>0.0</ixy>
                    <ixz>0.0</ixz>
                    <iyy>0.004244</iyy>
                    <iyz>0.0</iyz>
                    <izz>0.00677</izz>
                </inertia>
                <mass>1.3118</mass>
            </inertial>
            <collision name="drive_wheel_left_collision">
                <pose>0.074873 0.34278 0.086706 0 0 0</pose>
                <geometry>
                    <mesh>
                        <uri>model://robot/meshes/drive_wheel_left.STL</uri>
                        <!-- <scale>0.001 0.001 0.001</scale> -->
                    </mesh>
                </geometry>
                <!-- <surface>
                    <friction>
                        <ode>
                            <mu>100000.0</mu>
                            <mu2>100000.0</mu2>
                            <fdir1>0 1 0</fdir1>
                            <slip1>0.0</slip1>
                            <slip2>0.0</slip2>
                        </ode>
                    </friction>
                    <contact>
                        <ode>
                            <soft_cfm>0</soft_cfm>
                            <soft_erp>0.2</soft_erp>
                            <kp>1e+5</kp>
                            <kd>1</kd>
                            <max_vel>0.01</max_vel>
                            <min_depth>0.001</min_depth>
                        </ode>
                    </contact>
                </surface> -->
            </collision>
            <visual name="drive_wheel_left_visual">
                <pose>0.074873 0.34278 0.0867060 0 0</pose>
                <geometry>
                    <mesh>
                        <uri>model://robot/meshes/drive_wheel_left.STL</uri>
                        <!-- <scale>0.001 0.001 0.001</scale> -->
                    </mesh>
                </geometry>
                <material name="dark"/>
            </visual>
        </link>
        <joint name="drive_wheel_left_joint" type="revolute">
            <parent>base_footprint</parent>
            <child>drive_wheel_left</child>
            <pose>0.074873 0.34278 0.086706 0.0 0.0 0.0</pose>
            <axis>
                <xyz>0 1 0</xyz>
            </axis>
        </joint>

        <plugin name="diff_drive" filename="libgazebo_ros_diff_drive.so">

            <ros>
                <namespace>/robot</namespace>
            </ros>

            <update_rate>30</update_rate>

            <!-- wheels -->
            <left_joint>drive_wheel_left_joint</left_joint>
            <right_joint>drive_wheel_right_joint</right_joint>

            <!-- kinematics -->
            <wheel_separation>0.6855600</wheel_separation>
            <wheel_diameter>0.4064000</wheel_diameter>

            <!-- limits -->
            <max_wheel_torque>20</max_wheel_torque>
            <max_wheel_acceleration>1.0</max_wheel_acceleration>

            <command_topic>cmd_vel</command_topic>

            <!-- output -->
            <publish_odom>true</publish_odom>
            <publish_odom_tf>true</publish_odom_tf>
            <publish_wheel_tf>false</publish_wheel_tf>

            <odometry_topic>odom</odometry_topic>
            <odometry_frame>odom</odometry_frame>
            <robot_base_frame>base_footprint</robot_base_frame>

        </plugin>

        <plugin name="joint_state" filename="libgazebo_ros_joint_state_publisher.so">
            <ros>
                <!-- <namespace>/tb3</namespace> -->
                <remapping>~/out:=joint_states</remapping>
            </ros>
            <update_rate>30</update_rate>
            <joint_name>drive_wheel_left_joint</joint_name>
            <joint_name>drive_wheel_right_joint</joint_name>
        </plugin>

        <link name="laserscan_front">
            <inertial>
                <pose>0.02471 6.5845E-10 -0.011912 0 0 0</pose>
                <inertia>
                    <ixx>0.001</ixx>
                    <ixy>0.0</ixy>
                    <ixz>0.0</ixz>
                    <iyy>0.001</iyy>
                    <iyz>0.0</iyz>
                    <izz>0.001</izz>
                </inertia>
                <mass>0.32341</mass>
            </inertial>
            <collision name="laserscan_front_collision">
                <pose>0.76419 0.351 0.28335 0 0 0</pose>
                <geometry>
                    <mesh>
                        <uri>model://robot/meshes/laserscan_front.STL</uri>
                        <!-- <scale>0.001 0.001 0.001</scale> -->
                    </mesh>
                </geometry>
            </collision>
            <visual name="laserscan_front_visual">
                <pose>0.76419 0.351 0.28335 0 0 0</pose>
                <geometry>
                    <mesh>
                        <uri>model://robot/meshes/laserscan_front.STL</uri>
                        <!-- <scale>0.001 0.001 0.001</scale> -->
                    </mesh>
                </geometry>
                <material name="grey"/>
            </visual>
            <sensor type="ray" name="head_hokuyo_sensor">
                <pose>0.76419 0.351 0.28335 0 0 0</pose>
                <ray>
                    <scan>
                        <horizontal>
                            <samples>720</samples>
                            <resolution>1</resolution>
                            <min_angle>-2.35619</min_angle>
                            <max_angle>2.35619</max_angle>
                        </horizontal>
                    </scan>
                    <range>
                        <min>0.10</min>
                        <max>40.0</max>
                        <resolution>0.001</resolution>
                    </range>
                </ray>
                <always_on>true</always_on>
                <visualize>true</visualize>
                <update_rate>40</update_rate>
                <plugin name="gazebo_ros_head_hokuyo_controller" filename="libgazebo_ros_ray_sensor.so">
                    <ros>
                        <namespace>/laser_back</namespace>
                        <remapping>~/out:=scan</remapping>
                    </ros>
                    <output_type>sensor_msgs/LaserScan</output_type>
                    <frameName>laserscan_front</frameName>
                </plugin>
            </sensor>
        </link>
        <joint name="laserscan_front_joint" type="fixed">
            <parent>base_link</parent>
            <child>laserscan_front</child>
            <pose>0.76419 0.351 0.28335 0.0 0.0 0.0</pose>
        </joint>

        <link name="laserscan_back">
            <inertial>
                <pose>0.02471 6.5845E-10 -0.011912 0 0 0</pose>
                <inertia>
                    <ixx>0.001</ixx>
                    <ixy>0.0</ixy>
                    <ixz>0.0</ixz>
                    <iyy>0.001</iyy>
                    <iyz>0.0</iyz>
                    <izz>0.001</izz>
                </inertia>
                <mass>0.32341</mass>
            </inertial>
            <collision name="laserscan_back_collision">
                <pose>-0.76419 -0.351 0.28335 0 0 3.14</pose>
                <geometry>
                    <mesh>
                        <uri>model://robot/meshes/laserscan_back.STL</uri>
                        <!-- <scale>0.001 0.001 0.001</scale> -->
                    </mesh>
                </geometry>
            </collision>
            <visual name="laserscan_back_visual">
                <pose>-0.76419 -0.351 0.28335 0 0 3.14</pose>
                <geometry>
                    <mesh>
                        <uri>model://robot/meshes/laserscan_back.STL</uri>
                        <!-- <scale>0.001 0.001 0.001</scale> -->
                    </mesh>
                </geometry>
                <material name="grey"/>
            </visual>
            <sensor type="ray" name="head_hokuyo_sensor">
                <pose>-0.76419 -0.351 0.28335 0 0 3.14</pose>
                <ray>
                    <scan>
                        <horizontal>
                            <samples>720</samples>
                            <resolution>1</resolution>
                            <min_angle>-2.35619</min_angle>
                            <max_angle>2.35619</max_angle>
                        </horizontal>
                    </scan>
                    <range>
                        <min>0.10</min>
                        <max>40.0</max>
                        <resolution>0.001</resolution>
                    </range>
                </ray>
                <always_on>true</always_on>
                <visualize>true</visualize>
                <update_rate>40</update_rate>
                <plugin name="gazebo_ros_head_hokuyo_controller" filename="libgazebo_ros_ray_sensor.so">
                    <ros>
                        <namespace>/laser_front</namespace>
                        <remapping>~/out:=scan</remapping>
                    </ros>
                    <output_type>sensor_msgs/LaserScan</output_type>
                    <frameName>laserscan_back</frameName>
                </plugin>
            </sensor>
        </link>
        <joint name="laserscan_back_joint" type="fixed">
            <parent>base_link</parent>
            <child>laserscan_back</child>
            <pose>-0.76419 -0.351 0.28335 0.0 0.0 3.14</pose>
        </joint>

        <link name="imu_link">
            <inertial>
                <pose>0 0 0.00122 0.0 0.0 0.0</pose>
                <inertia>
                    <ixx>0.001</ixx>
                    <ixy>0.0</ixy>
                    <ixz>0.0</ixz>
                    <iyy>0.001</iyy>
                    <iyz>0.0</iyz>
                    <izz>0.001</izz>
                </inertia>
                <mass>0.32341</mass>
            </inertial>
            <collision name="imu_link_collision">
                <pose>0 0 0.00122 0.0 0.0 0.0</pose>
                <geometry>
                    <mesh>
                        <uri>model://robot/meshes/imu_adis1647x_pcb.STL</uri>
                        <!-- <scale>0.001 0.001 0.001</scale> -->
                    </mesh>
                </geometry>
            </collision>
            <visual name="imu_link_visual">
                <pose>0 0 0.00122 0.0 0.0 0.0</pose>
                <geometry>
                    <mesh>
                        <uri>model://robot/meshes/imu_adis1647x_pcb.STL</uri>
                        <!-- <scale>0.001 0.001 0.001</scale> -->
                    </mesh>
                </geometry>
            </visual>
            <sensor name="imu_sensor" type="imu">
                <plugin filename="libgazebo_ros_imu_sensor.so" name="imu_plugin">
                    <ros>
                        <namespace>/imu</namespace>
                        <remapping>~/out:=imu</remapping>
                    </ros>
                    <bodyName>imu_adis1647x_pcb</bodyName>
                    <updateRateHZ>10.0</updateRateHZ>
                    <gaussianNoise>0.0</gaussianNoise>
                    <xyzOffset>0 0 0</xyzOffset>
                    <rpyOffset>0 0 0</rpyOffset>
                    <frameName>imu_link</frameName>
                    <initial_orientation_as_reference>false</initial_orientation_as_reference>
                </plugin>
                <always_on>true</always_on>
                <update_rate>100</update_rate>
                <visualize>true</visualize>

            </sensor>
        </link>
        <joint name="imu_link_joint" type="fixed">
            <parent>base_link</parent>
            <child>imu_link</child>
            <pose>0 0 0.00122 0.0 0.0 0.0</pose>
        </joint>


    </model>
</sdf>
